<?xml version="1.0" ?>
<!-- =================================================================================== -->
<!-- |    This document was autogenerated by xacro from brov2.xacro                    | -->
<!-- |    EDITING THIS FILE BY HAND IS NOT RECOMMENDED                                 | -->
<!-- =================================================================================== -->
<!-- =================================================================================== -->
<!-- |    This document was autogenerated by xacro from brov2_base.xacro               | -->
<!-- |    EDITING THIS FILE BY HAND IS NOT RECOMMENDED                                 | -->
<!-- =================================================================================== -->
<robot name="auv">
  <material name="brovgrey">
    <color rgba="0.25 0.25 0.28 1"/>
  </material>
  <!-- Plugin list -->
  <gazebo>
    <!-- Gazebo plugin listens to the body-->
    <plugin filename="libfreefloating_gazebo_control.so" name="freefloating_gazebo_control">
      <switchService>switch</switchService>
      <updateRate>100</updateRate>
      <link>base_link</link>
      <!-- for each thruster, give the map to XYZ+RPY and the maximum effort -->
      <!-- alternatively, give a link name + the maximum effort -->
      <thruster>
        <effort>40</effort>
        <name>thr1</name>
      </thruster>
      <thruster>
        <effort>40</effort>
        <name>thr2</name>
      </thruster>
      <thruster>
        <effort>30</effort>
        <name>thr3</name>
      </thruster>
      <thruster>
        <effort>30</effort>
        <name>thr4</name>
      </thruster>
      <thruster>
        <effort>30</effort>
        <name>thr5</name>
      </thruster>
      <thruster>
        <effort>30</effort>
        <name>thr6</name>
      </thruster>
    </plugin>
  </gazebo>
  <gazebo reference="base_link">
    <visual>
      <material>
        <ambient>0.25 0.25 0.28 1.0</ambient>
        <diffuse>0.25 0.25 0.28 1.0</diffuse>
        <specular>0.25 0.25 0.28 1.0</specular>
        <emissive>0.0 0.0 0.0 0.0</emissive>
      </material>
    </visual>
  </gazebo>
  <link name="base_link">
    <visual>
      <!--       <origin rpy="1.57079632679 0 1.57079632679" xyz="0.1 -0.167 -0.19"/> -->
      <origin rpy="0 0 0" xyz="0 0 0"/>
      <geometry>
        <mesh filename="package://ecn_rasom/urdf/bluerov2_noprop.dae"/>
      </geometry>
      <material name="brovgrey"/>
    </visual>
    <inertial>
      <origin rpy="0 0 0" xyz="0 0 -0.1"/>
      <mass value="7.5"/>
      <inertia ixx="5" ixy="0.0" ixz="0.0" iyy="5" iyz="5" izz="5"/>
    </inertial>
    <fluid>
      <density>1</density>
      <origin xyz="0 0 0"/>
      <buoyancy>
        <compensation>1.01</compensation>
        <limit radius="0.01"/>
      </buoyancy>
      <hydrodynamics>
        <drag rpy="50 50 50" type="linear" xyz="50 100 60"/>
        <!--             <drag xyz="50 100 60" rpy="50 50 50" type="quadratic"/> -->
      </hydrodynamics>
    </fluid>
  </link>
  <link name="camera">
    <visual>
      <geometry>
        <cylinder length="0.03" radius="0.01"/>
      </geometry>
      <material name="black">
        <color rgba="0 0 0 1"/>
      </material>
    </visual>
    <inertial>
      <mass value="0.001"/>
      <inertia ixx="0.001" ixy="0.0" ixz="0.0" iyy="0.001" iyz="0" izz="0.001"/>
    </inertial>
  </link>
  
  
  <gazebo reference="camera">
    <material>Gazebo/Black</material>
  </gazebo>
  <joint name="tilt" type="revolute">
    <parent link="base_link"/>
    <child link="camera"/>
    <origin rpy="0 1.57079632679 0" xyz="0.17 0 0"/>
    <axis xyz="0 1 0"/>
    <limit effort="100" lower="-0.785398163397" upper="0.785398163397" velocity="5.0"/>
    <dynamics damping="0.8"/>
  </joint>
  <joint name="thr1" type="fixed">
    <parent link="base_link"/>
    <child link="thr1"/>
    <origin rpy="0.0 1.57079632679 0.785398163397" xyz="0.125 -0.115 -0.07"/>
  </joint>
  <link name="thr1"/>
  <joint name="thr2" type="fixed">
    <parent link="base_link"/>
    <child link="thr2"/>
    <origin rpy="0.0 1.57079632679 -0.785398163397" xyz="0.125 0.115 -0.07"/>
  </joint>
  <link name="thr2"/>
  <joint name="thr3" type="fixed">
    <parent link="base_link"/>
    <child link="thr3"/>
    <origin rpy="0.0 1.57079632679 2.35619449019" xyz="-0.15 -0.115 -0.07"/>
  </joint>
  <link name="thr3"/>
  <joint name="thr4" type="fixed">
    <parent link="base_link"/>
    <child link="thr4"/>
    <origin rpy="0.0 1.57079632679 3.92699081699" xyz="-0.15 0.115 -0.07"/>
  </joint>
  <link name="thr4"/>
  <joint name="thr5" type="fixed">
    <parent link="base_link"/>
    <child link="thr5"/>
    <origin rpy="0.0 0 0.0" xyz="0.0 -0.11 0"/>
  </joint>
  <link name="thr5"/>
  <joint name="thr6" type="fixed">
    <parent link="base_link"/>
    <child link="thr6"/>
    <origin rpy="0.0 0 0.0" xyz="0.0 0.11 0"/>
  </joint>
  <link name="thr6"/>
  <link name="lsm"/>
  <link name="mpu"/>
  <joint name="lsm" type="fixed">
    <parent link="base_link"/>
    <child link="lsm"/>
    <origin rpy="0 0 0" xyz=".12 0.018 0.02"/>
  </joint>
  <gazebo reference="lsm">
    <sensor name="imu_sensor" type="imu">
      <always_on>true</always_on>
      <update_rate>100</update_rate>
      <visualize>true</visualize>
      <plugin filename="libgazebo_ros_imu_sensor.so" name="imu_plugin">
        <topicName>lsm</topicName>
        <bodyName>base_link</bodyName>
        <updateRateHZ>1000.0</updateRateHZ>
        <gaussianNoise>0.001</gaussianNoise>
        <xyzOffset>.12 0.018 0.02</xyzOffset>
        <rpyOffset>0 0 0</rpyOffset>
        <frameName>lsm</frameName>
      </plugin>
    </sensor>
  </gazebo>
  <joint name="mpu" type="fixed">
    <parent link="base_link"/>
    <child link="mpu"/>
    <origin rpy="0 0 0" xyz=".13 0.018 0.02"/>
  </joint>
  <gazebo reference="mpu">
    <sensor name="imu_sensor" type="imu">
      <always_on>true</always_on>
      <update_rate>100</update_rate>
      <visualize>true</visualize>
      <plugin filename="libgazebo_ros_imu_sensor.so" name="imu_plugin">
        <topicName>mpu</topicName>
        <bodyName>base_link</bodyName>
        <updateRateHZ>1000.0</updateRateHZ>
        <gaussianNoise>0.001</gaussianNoise>
        <xyzOffset>.13 0.018 0.02</xyzOffset>
        <rpyOffset>0 0 0</rpyOffset>
        <frameName>mpu</frameName>
      </plugin>
    </sensor>
  </gazebo>
</robot>

